const HttpError = require("../models/http-error");

const User = require("../models/user-model");

const getAllUsers = async (req, res, next) => {
  let users;
  try {
    users = await User.find({}, "-password");
  } catch (err) {
    const error = new HttpError("No user found.", 404);
    return next(error);
  }
  res
    .status(200)
    .json({ users: users.map((user) => user.toObject({ getters: true })) });
};

const signUp = async (req, res, next) => {
  const { name, email, password } = req.body;

  let existingUser;
  try {
    existingUser = await User.findOne({ email: email });
  } catch (err) {
    const error = new HttpError(
      "Signing up failed, please try again later.",
      500
    );
    return next(error);
  }

  if (existingUser) {
    const error = new HttpError(
      "User exists already, please login instead.",
      422
    );
    return next(error);
  }

  const createdUser = new User({
    name,
    email,
    image: req.file.path,
    password,
    places: [],
  });

  try {
    await createdUser.save();
  } catch (err) {
    const error = new HttpError(
      "Signing up failed, please try again later.",
      500
    );
    return next(error);
  }

  res.status(201).json({ user: createdUser.toObject({ getters: true }) });
};

const login = async (req, res, next) => {
  const { email, password } = req.body;

  let existingUser;

  try {
    existingUser = await User.findOne({ email: email });
  } catch (err) {
    const error = new HttpError(
      "Loggin in failed, please try again later.",
      500
    );
    return next(error);
  }

  if (!existingUser || existingUser.password !== password) {
    const error = new HttpError(
      "Invalid credentials, could not log you in.",
      401
    );
    return next(error);
  }

  res.json({
    message: "Logged in!",
    user: existingUser.toObject({ getters: true }),
  });
};

module.exports = {
  getAllUsers,
  signUp,
  login,
};
